/*
 * Copyright (c) 2026 Kalishak
 *
 * Licensed under the MIT license
 * See LICENSE file for more details
 */

package io.kalishak.galacticraftlegacy.world.level.levelgen.features;

import com.mojang.serialization.MapCodec;
import io.kalishak.galacticraftlegacy.world.level.block.GalacticraftBlocks;
import net.minecraft.core.BlockPos;
import net.minecraft.util.RandomSource;
import net.minecraft.world.level.WorldGenLevel;
import net.minecraft.world.level.block.Block;
import net.minecraft.world.level.block.Blocks;
import net.minecraft.world.level.chunk.ChunkGenerator;
import net.minecraft.world.level.levelgen.feature.Feature;

public record SpaceStationFeature() implements Feature {
    public static final MapCodec<SpaceStationFeature> MAP_CODEC = MapCodec.unit(SpaceStationFeature::new);

    @Override
    public MapCodec<SpaceStationFeature> codec() {
        return MAP_CODEC;
    }

    @Override
    public boolean place(WorldGenLevel level, ChunkGenerator chunkGenerator, RandomSource random, BlockPos origin) {
        level.setBlock(origin.offset(0, 0, 0), GalacticraftBlocks.TIN_DECORATION_BLOCK.get().defaultBlockState(), Block.UPDATE_CLIENTS);
        level.setBlock(origin.offset(0, 0, 1), GalacticraftBlocks.TIN_DECORATION_BLOCK.get().defaultBlockState(), Block.UPDATE_CLIENTS);
        level.setBlock(origin.offset(0, 0, 2), GalacticraftBlocks.TIN_DECORATION_BLOCK.get().defaultBlockState(), Block.UPDATE_CLIENTS);
        level.setBlock(origin.offset(0, 0, 3), GalacticraftBlocks.TIN_DECORATION_BLOCK.get().defaultBlockState(), Block.UPDATE_CLIENTS);
        level.setBlock(origin.offset(0, 0, 4), GalacticraftBlocks.TIN_DECORATION_BLOCK.get().defaultBlockState(), Block.UPDATE_CLIENTS);
        level.setBlock(origin.offset(0, 0, 5), GalacticraftBlocks.TIN_DECORATION_BLOCK.get().defaultBlockState(), Block.UPDATE_CLIENTS);
        level.setBlock(origin.offset(0, 0, 6), GalacticraftBlocks.TIN_DECORATION_BLOCK.get().defaultBlockState(), Block.UPDATE_CLIENTS);
        level.setBlock(origin.offset(0, 1, 0), GalacticraftBlocks.TIN_DECORATION_BLOCK.get().defaultBlockState(), Block.UPDATE_CLIENTS);
        level.setBlock(origin.offset(0, 1, 1), GalacticraftBlocks.TIN_DECORATION_BLOCK.get().defaultBlockState(), Block.UPDATE_CLIENTS);
        level.setBlock(origin.offset(0, 1, 2), GalacticraftBlocks.TIN_DECORATION_BLOCK.get().defaultBlockState(), Block.UPDATE_CLIENTS);
        level.setBlock(origin.offset(0, 1, 3), GalacticraftBlocks.TIN_DECORATION_BLOCK.get().defaultBlockState(), Block.UPDATE_CLIENTS);
        level.setBlock(origin.offset(0, 1, 4), GalacticraftBlocks.TIN_DECORATION_BLOCK.get().defaultBlockState(), Block.UPDATE_CLIENTS);
        level.setBlock(origin.offset(0, 1, 5), GalacticraftBlocks.TIN_DECORATION_BLOCK.get().defaultBlockState(), Block.UPDATE_CLIENTS);
        level.setBlock(origin.offset(0, 1, 6), GalacticraftBlocks.TIN_DECORATION_BLOCK.get().defaultBlockState(), Block.UPDATE_CLIENTS);
        level.setBlock(origin.offset(1, 0, 0), GalacticraftBlocks.TIN_DECORATION_BLOCK.get().defaultBlockState(), Block.UPDATE_CLIENTS);
        level.setBlock(origin.offset(1, 0, 1), GalacticraftBlocks.TIN_DECORATION_BLOCK.get().defaultBlockState(), Block.UPDATE_CLIENTS);
        level.setBlock(origin.offset(1, 0, 2), GalacticraftBlocks.TIN_DECORATION_BLOCK.get().defaultBlockState(), Block.UPDATE_CLIENTS);
        level.setBlock(origin.offset(1, 0, 3), GalacticraftBlocks.TIN_DECORATION_BLOCK.get().defaultBlockState(), Block.UPDATE_CLIENTS);
        level.setBlock(origin.offset(1, 0, 4), GalacticraftBlocks.TIN_DECORATION_BLOCK.get().defaultBlockState(), Block.UPDATE_CLIENTS);
        level.setBlock(origin.offset(1, 0, 5), GalacticraftBlocks.TIN_DECORATION_BLOCK.get().defaultBlockState(), Block.UPDATE_CLIENTS);
        level.setBlock(origin.offset(1, 0, 6), GalacticraftBlocks.TIN_DECORATION_BLOCK.get().defaultBlockState(), Block.UPDATE_CLIENTS);
        level.setBlock(origin.offset(1, 1, 0), GalacticraftBlocks.TIN_DECORATION_BLOCK.get().defaultBlockState(), Block.UPDATE_CLIENTS);
        level.setBlock(origin.offset(1, 1, 6), GalacticraftBlocks.TIN_DECORATION_BLOCK.get().defaultBlockState(), Block.UPDATE_CLIENTS);
        level.setBlock(origin.offset(2, 0, 0), GalacticraftBlocks.TIN_DECORATION_BLOCK.get().defaultBlockState(), Block.UPDATE_CLIENTS);
        level.setBlock(origin.offset(2, 0, 1), GalacticraftBlocks.TIN_DECORATION_BLOCK.get().defaultBlockState(), Block.UPDATE_CLIENTS);
        level.setBlock(origin.offset(2, 0, 2), GalacticraftBlocks.TIN_DECORATION_BLOCK.get().defaultBlockState(), Block.UPDATE_CLIENTS);
        level.setBlock(origin.offset(2, 0, 3), GalacticraftBlocks.TIN_DECORATION_BLOCK.get().defaultBlockState(), Block.UPDATE_CLIENTS);
        level.setBlock(origin.offset(2, 0, 4), GalacticraftBlocks.TIN_DECORATION_BLOCK.get().defaultBlockState(), Block.UPDATE_CLIENTS);
        level.setBlock(origin.offset(2, 0, 5), GalacticraftBlocks.TIN_DECORATION_BLOCK.get().defaultBlockState(), Block.UPDATE_CLIENTS);
        level.setBlock(origin.offset(2, 0, 6), GalacticraftBlocks.TIN_DECORATION_BLOCK.get().defaultBlockState(), Block.UPDATE_CLIENTS);
        level.setBlock(origin.offset(2, 1, 0), GalacticraftBlocks.TIN_DECORATION_BLOCK.get().defaultBlockState(), Block.UPDATE_CLIENTS);
        level.setBlock(origin.offset(2, 1, 6), GalacticraftBlocks.TIN_DECORATION_BLOCK.get().defaultBlockState(), Block.UPDATE_CLIENTS);
        level.setBlock(origin.offset(3, 0, 0), GalacticraftBlocks.TIN_DECORATION_BLOCK.get().defaultBlockState(), Block.UPDATE_CLIENTS);
        level.setBlock(origin.offset(3, 0, 1), GalacticraftBlocks.TIN_DECORATION_BLOCK.get().defaultBlockState(), Block.UPDATE_CLIENTS);
        level.setBlock(origin.offset(3, 0, 2), GalacticraftBlocks.TIN_DECORATION_BLOCK.get().defaultBlockState(), Block.UPDATE_CLIENTS);
        level.setBlock(origin.offset(3, 0, 3), GalacticraftBlocks.TIN_DECORATION_BLOCK.get().defaultBlockState(), Block.UPDATE_CLIENTS);
        level.setBlock(origin.offset(3, 0, 4), GalacticraftBlocks.TIN_DECORATION_BLOCK.get().defaultBlockState(), Block.UPDATE_CLIENTS);
        level.setBlock(origin.offset(3, 0, 5), GalacticraftBlocks.TIN_DECORATION_BLOCK.get().defaultBlockState(), Block.UPDATE_CLIENTS);
        level.setBlock(origin.offset(3, 0, 6), GalacticraftBlocks.TIN_DECORATION_BLOCK.get().defaultBlockState(), Block.UPDATE_CLIENTS);
        level.setBlock(origin.offset(3, 1, 0), GalacticraftBlocks.TIN_DECORATION_BLOCK.get().defaultBlockState(), Block.UPDATE_CLIENTS);

        level.setBlock(origin.offset(3, 1, 6), GalacticraftBlocks.TIN_DECORATION_BLOCK.get().defaultBlockState(), Block.UPDATE_CLIENTS);
        level.setBlock(origin.offset(4, 0, 0), GalacticraftBlocks.TIN_DECORATION_BLOCK.get().defaultBlockState(), Block.UPDATE_CLIENTS);
        level.setBlock(origin.offset(4, 0, 1), GalacticraftBlocks.TIN_DECORATION_BLOCK.get().defaultBlockState(), Block.UPDATE_CLIENTS);
        level.setBlock(origin.offset(4, 0, 2), GalacticraftBlocks.TIN_DECORATION_BLOCK.get().defaultBlockState(), Block.UPDATE_CLIENTS);
        level.setBlock(origin.offset(4, 0, 3), GalacticraftBlocks.TIN_DECORATION_BLOCK.get().defaultBlockState(), Block.UPDATE_CLIENTS);
        level.setBlock(origin.offset(4, 0, 4), GalacticraftBlocks.TIN_DECORATION_BLOCK.get().defaultBlockState(), Block.UPDATE_CLIENTS);
        level.setBlock(origin.offset(4, 0, 5), GalacticraftBlocks.TIN_DECORATION_BLOCK.get().defaultBlockState(), Block.UPDATE_CLIENTS);
        level.setBlock(origin.offset(4, 0, 6), GalacticraftBlocks.TIN_DECORATION_BLOCK.get().defaultBlockState(), Block.UPDATE_CLIENTS);
        level.setBlock(origin.offset(4, 1, 0), GalacticraftBlocks.TIN_DECORATION_BLOCK.get().defaultBlockState(), Block.UPDATE_CLIENTS);
        level.setBlock(origin.offset(4, 1, 6), GalacticraftBlocks.TIN_DECORATION_BLOCK.get().defaultBlockState(), Block.UPDATE_CLIENTS);
        level.setBlock(origin.offset(5, 0, 0), GalacticraftBlocks.TIN_DECORATION_BLOCK.get().defaultBlockState(), Block.UPDATE_CLIENTS);
        level.setBlock(origin.offset(5, 0, 1), GalacticraftBlocks.TIN_DECORATION_BLOCK.get().defaultBlockState(), Block.UPDATE_CLIENTS);
        level.setBlock(origin.offset(5, 0, 2), GalacticraftBlocks.TIN_DECORATION_BLOCK.get().defaultBlockState(), Block.UPDATE_CLIENTS);
        level.setBlock(origin.offset(5, 0, 3), GalacticraftBlocks.TIN_DECORATION_BLOCK.get().defaultBlockState(), Block.UPDATE_CLIENTS);
        level.setBlock(origin.offset(5, 0, 4), GalacticraftBlocks.TIN_DECORATION_BLOCK.get().defaultBlockState(), Block.UPDATE_CLIENTS);
        level.setBlock(origin.offset(5, 0, 5), GalacticraftBlocks.TIN_DECORATION_BLOCK.get().defaultBlockState(), Block.UPDATE_CLIENTS);
        level.setBlock(origin.offset(5, 0, 6), GalacticraftBlocks.TIN_DECORATION_BLOCK.get().defaultBlockState(), Block.UPDATE_CLIENTS);
        level.setBlock(origin.offset(5, 1, 0), GalacticraftBlocks.TIN_DECORATION_BLOCK.get().defaultBlockState(), Block.UPDATE_CLIENTS);
        level.setBlock(origin.offset(5, 1, 6), GalacticraftBlocks.TIN_DECORATION_BLOCK.get().defaultBlockState(), Block.UPDATE_CLIENTS);
        level.setBlock(origin.offset(6, 1, 0), GalacticraftBlocks.TIN_DECORATION_BLOCK.get().defaultBlockState(), Block.UPDATE_CLIENTS);
        level.setBlock(origin.offset(6, 1, 1), GalacticraftBlocks.TIN_DECORATION_BLOCK.get().defaultBlockState(), Block.UPDATE_CLIENTS);
        level.setBlock(origin.offset(6, 1, 2), GalacticraftBlocks.TIN_DECORATION_BLOCK.get().defaultBlockState(), Block.UPDATE_CLIENTS);
        level.setBlock(origin.offset(6, 1, 3), GalacticraftBlocks.TIN_DECORATION_BLOCK.get().defaultBlockState(), Block.UPDATE_CLIENTS);
        level.setBlock(origin.offset(6, 1, 4), GalacticraftBlocks.TIN_DECORATION_BLOCK.get().defaultBlockState(), Block.UPDATE_CLIENTS);
        level.setBlock(origin.offset(6, 1, 5), GalacticraftBlocks.TIN_DECORATION_BLOCK.get().defaultBlockState(), Block.UPDATE_CLIENTS);
        level.setBlock(origin.offset(6, 1, 6), GalacticraftBlocks.TIN_DECORATION_BLOCK.get().defaultBlockState(), Block.UPDATE_CLIENTS);
        level.setBlock(origin.offset(6, 2, 0), GalacticraftBlocks.TIN_DECORATION_BLOCK.get().defaultBlockState(), Block.UPDATE_CLIENTS);
        level.setBlock(origin.offset(6, 2, 6), GalacticraftBlocks.TIN_DECORATION_BLOCK.get().defaultBlockState(), Block.UPDATE_CLIENTS);
        level.setBlock(origin.offset(6, 3, 0), GalacticraftBlocks.TIN_DECORATION_BLOCK.get().defaultBlockState(), Block.UPDATE_CLIENTS);
        level.setBlock(origin.offset(6, 3, 6), GalacticraftBlocks.TIN_DECORATION_BLOCK.get().defaultBlockState(), Block.UPDATE_CLIENTS);
        level.setBlock(origin.offset(6, 4, 0), GalacticraftBlocks.TIN_DECORATION_BLOCK.get().defaultBlockState(), Block.UPDATE_CLIENTS);
        level.setBlock(origin.offset(6, 4, 6), GalacticraftBlocks.TIN_DECORATION_BLOCK.get().defaultBlockState(), Block.UPDATE_CLIENTS);
        level.setBlock(origin.offset(6, 5, 0), GalacticraftBlocks.TIN_DECORATION_BLOCK.get().defaultBlockState(), Block.UPDATE_CLIENTS);
        level.setBlock(origin.offset(6, 5, 1), GalacticraftBlocks.TIN_DECORATION_BLOCK.get().defaultBlockState(), Block.UPDATE_CLIENTS);
        level.setBlock(origin.offset(6, 5, 2), GalacticraftBlocks.TIN_DECORATION_BLOCK.get().defaultBlockState(), Block.UPDATE_CLIENTS);
        level.setBlock(origin.offset(6, 5, 3), GalacticraftBlocks.TIN_DECORATION_BLOCK.get().defaultBlockState(), Block.UPDATE_CLIENTS);
        level.setBlock(origin.offset(6, 5, 4), GalacticraftBlocks.TIN_DECORATION_BLOCK.get().defaultBlockState(), Block.UPDATE_CLIENTS);
        level.setBlock(origin.offset(6, 5, 5), GalacticraftBlocks.TIN_DECORATION_BLOCK.get().defaultBlockState(), Block.UPDATE_CLIENTS);
        level.setBlock(origin.offset(6, 5, 6), GalacticraftBlocks.TIN_DECORATION_BLOCK.get().defaultBlockState(), Block.UPDATE_CLIENTS);
        level.setBlock(origin.offset(7, 1, 0), GalacticraftBlocks.TIN_DECORATION_BLOCK.get().defaultBlockState(), Block.UPDATE_CLIENTS);
        level.setBlock(origin.offset(7, 1, 1), GalacticraftBlocks.TIN_DECORATION_BLOCK.get().defaultBlockState(), Block.UPDATE_CLIENTS);
        level.setBlock(origin.offset(7, 1, 2), GalacticraftBlocks.TIN_DECORATION_BLOCK.get().defaultBlockState(), Block.UPDATE_CLIENTS);
        level.setBlock(origin.offset(7, 1, 3), GalacticraftBlocks.TIN_DECORATION_BLOCK.get().defaultBlockState(), Block.UPDATE_CLIENTS);
        level.setBlock(origin.offset(7, 1, 4), GalacticraftBlocks.TIN_DECORATION_BLOCK.get().defaultBlockState(), Block.UPDATE_CLIENTS);
        level.setBlock(origin.offset(7, 1, 5), GalacticraftBlocks.TIN_DECORATION_BLOCK.get().defaultBlockState(), Block.UPDATE_CLIENTS);
        level.setBlock(origin.offset(7, 1, 6), GalacticraftBlocks.TIN_DECORATION_BLOCK.get().defaultBlockState(), Block.UPDATE_CLIENTS);
        level.setBlock(origin.offset(7, 2, 0), GalacticraftBlocks.TIN_DECORATION_BLOCK.get().defaultBlockState(), Block.UPDATE_CLIENTS);
        level.setBlock(origin.offset(7, 2, 1), GalacticraftBlocks.TIN_DECORATION_BLOCK.get().defaultBlockState(), Block.UPDATE_CLIENTS);
        level.setBlock(origin.offset(7, 2, 5), GalacticraftBlocks.TIN_DECORATION_BLOCK.get().defaultBlockState(), Block.UPDATE_CLIENTS);
        level.setBlock(origin.offset(7, 2, 6), GalacticraftBlocks.TIN_DECORATION_BLOCK.get().defaultBlockState(), Block.UPDATE_CLIENTS);
        level.setBlock(origin.offset(7, 3, 0), GalacticraftBlocks.TIN_DECORATION_BLOCK.get().defaultBlockState(), Block.UPDATE_CLIENTS);
        level.setBlock(origin.offset(7, 3, 1), GalacticraftBlocks.TIN_DECORATION_BLOCK.get().defaultBlockState(), Block.UPDATE_CLIENTS);
        level.setBlock(origin.offset(7, 3, 5), GalacticraftBlocks.TIN_DECORATION_BLOCK.get().defaultBlockState(), Block.UPDATE_CLIENTS);
        level.setBlock(origin.offset(7, 3, 6), GalacticraftBlocks.TIN_DECORATION_BLOCK.get().defaultBlockState(), Block.UPDATE_CLIENTS);
        level.setBlock(origin.offset(7, 4, 0), GalacticraftBlocks.TIN_DECORATION_BLOCK.get().defaultBlockState(), Block.UPDATE_CLIENTS);
        level.setBlock(origin.offset(7, 4, 1), GalacticraftBlocks.TIN_DECORATION_BLOCK.get().defaultBlockState(), Block.UPDATE_CLIENTS);
        level.setBlock(origin.offset(7, 4, 5), GalacticraftBlocks.TIN_DECORATION_BLOCK.get().defaultBlockState(), Block.UPDATE_CLIENTS);
        level.setBlock(origin.offset(7, 4, 6), GalacticraftBlocks.TIN_DECORATION_BLOCK.get().defaultBlockState(), Block.UPDATE_CLIENTS);
        level.setBlock(origin.offset(7, 5, 0), GalacticraftBlocks.TIN_DECORATION_BLOCK.get().defaultBlockState(), Block.UPDATE_CLIENTS);
        level.setBlock(origin.offset(7, 5, 1), GalacticraftBlocks.TIN_DECORATION_BLOCK.get().defaultBlockState(), Block.UPDATE_CLIENTS);
        level.setBlock(origin.offset(7, 5, 2), GalacticraftBlocks.TIN_DECORATION_BLOCK.get().defaultBlockState(), Block.UPDATE_CLIENTS);
        level.setBlock(origin.offset(7, 5, 3), GalacticraftBlocks.TIN_DECORATION_BLOCK.get().defaultBlockState(), Block.UPDATE_CLIENTS);
        level.setBlock(origin.offset(7, 5, 4), GalacticraftBlocks.TIN_DECORATION_BLOCK.get().defaultBlockState(), Block.UPDATE_CLIENTS);
        level.setBlock(origin.offset(7, 5, 5), GalacticraftBlocks.TIN_DECORATION_BLOCK.get().defaultBlockState(), Block.UPDATE_CLIENTS);
        level.setBlock(origin.offset(7, 5, 6), GalacticraftBlocks.TIN_DECORATION_BLOCK.get().defaultBlockState(), Block.UPDATE_CLIENTS);
        level.setBlock(origin.offset(7, 6, 0), GalacticraftBlocks.TIN_DECORATION_BLOCK.get().defaultBlockState(), Block.UPDATE_CLIENTS);
        level.setBlock(origin.offset(7, 6, 1), GalacticraftBlocks.TIN_DECORATION_BLOCK.get().defaultBlockState(), Block.UPDATE_CLIENTS);
        level.setBlock(origin.offset(7, 6, 2), GalacticraftBlocks.TIN_DECORATION_BLOCK.get().defaultBlockState(), Block.UPDATE_CLIENTS);
        level.setBlock(origin.offset(7, 6, 3), GalacticraftBlocks.TIN_DECORATION_BLOCK.get().defaultBlockState(), Block.UPDATE_CLIENTS);
        level.setBlock(origin.offset(7, 6, 4), GalacticraftBlocks.TIN_DECORATION_BLOCK.get().defaultBlockState(), Block.UPDATE_CLIENTS);
        level.setBlock(origin.offset(7, 6, 5), GalacticraftBlocks.TIN_DECORATION_BLOCK.get().defaultBlockState(), Block.UPDATE_CLIENTS);
        level.setBlock(origin.offset(7, 6, 6), GalacticraftBlocks.TIN_DECORATION_BLOCK.get().defaultBlockState(), Block.UPDATE_CLIENTS);
        level.setBlock(origin.offset(8, 1, 0), GalacticraftBlocks.TIN_DECORATION_BLOCK.get().defaultBlockState(), Block.UPDATE_CLIENTS);
        level.setBlock(origin.offset(8, 1, 1), GalacticraftBlocks.TIN_DECORATION_BLOCK.get().defaultBlockState(), Block.UPDATE_CLIENTS);
        level.setBlock(origin.offset(8, 1, 2), GalacticraftBlocks.TIN_DECORATION_BLOCK.get().defaultBlockState(), Block.UPDATE_CLIENTS);
        level.setBlock(origin.offset(8, 1, 3), GalacticraftBlocks.TIN_DECORATION_BLOCK.get().defaultBlockState(), Block.UPDATE_CLIENTS);
        level.setBlock(origin.offset(8, 1, 4), GalacticraftBlocks.TIN_DECORATION_BLOCK.get().defaultBlockState(), Block.UPDATE_CLIENTS);
        level.setBlock(origin.offset(8, 1, 5), GalacticraftBlocks.TIN_DECORATION_BLOCK.get().defaultBlockState(), Block.UPDATE_CLIENTS);
        level.setBlock(origin.offset(8, 1, 6), GalacticraftBlocks.TIN_DECORATION_BLOCK.get().defaultBlockState(), Block.UPDATE_CLIENTS);
        level.setBlock(origin.offset(8, 2, 0), GalacticraftBlocks.TIN_DECORATION_BLOCK.get().defaultBlockState(), Block.UPDATE_CLIENTS);
        level.setBlock(origin.offset(8, 2, 6), GalacticraftBlocks.TIN_DECORATION_BLOCK.get().defaultBlockState(), Block.UPDATE_CLIENTS);
        level.setBlock(origin.offset(8, 3, 0), Blocks.GLASS_PANE.defaultBlockState(), Block.UPDATE_ALL);
        level.setBlock(origin.offset(8, 3, 6), Blocks.GLASS_PANE.defaultBlockState(), Block.UPDATE_ALL);
        level.setBlock(origin.offset(8, 4, 0), GalacticraftBlocks.TIN_DECORATION_BLOCK.get().defaultBlockState(), Block.UPDATE_CLIENTS);
        level.setBlock(origin.offset(8, 4, 6), GalacticraftBlocks.TIN_DECORATION_BLOCK.get().defaultBlockState(), Block.UPDATE_CLIENTS);
        level.setBlock(origin.offset(8, 5, 0), GalacticraftBlocks.TIN_DECORATION_BLOCK.get().defaultBlockState(), Block.UPDATE_CLIENTS);
        level.setBlock(origin.offset(8, 5, 6), GalacticraftBlocks.TIN_DECORATION_BLOCK.get().defaultBlockState(), Block.UPDATE_CLIENTS);
        level.setBlock(origin.offset(8, 6, 0), GalacticraftBlocks.TIN_DECORATION_BLOCK.get().defaultBlockState(), Block.UPDATE_CLIENTS);
        level.setBlock(origin.offset(8, 6, 1), GalacticraftBlocks.TIN_DECORATION_BLOCK.get().defaultBlockState(), Block.UPDATE_CLIENTS);
        level.setBlock(origin.offset(8, 6, 2), GalacticraftBlocks.TIN_DECORATION_BLOCK.get().defaultBlockState(), Block.UPDATE_CLIENTS);
        level.setBlock(origin.offset(8, 6, 3), GalacticraftBlocks.TIN_DECORATION_BLOCK.get().defaultBlockState(), Block.UPDATE_CLIENTS);
        level.setBlock(origin.offset(8, 6, 4), GalacticraftBlocks.TIN_DECORATION_BLOCK.get().defaultBlockState(), Block.UPDATE_CLIENTS);
        level.setBlock(origin.offset(8, 6, 5), GalacticraftBlocks.TIN_DECORATION_BLOCK.get().defaultBlockState(), Block.UPDATE_CLIENTS);
        level.setBlock(origin.offset(8, 6, 6), GalacticraftBlocks.TIN_DECORATION_BLOCK.get().defaultBlockState(), Block.UPDATE_CLIENTS);
        level.setBlock(origin.offset(9, 1, 0), GalacticraftBlocks.TIN_DECORATION_BLOCK.get().defaultBlockState(), Block.UPDATE_CLIENTS);
        level.setBlock(origin.offset(9, 1, 1), GalacticraftBlocks.TIN_DECORATION_BLOCK.get().defaultBlockState(), Block.UPDATE_CLIENTS);
        level.setBlock(origin.offset(9, 1, 2), GalacticraftBlocks.TIN_DECORATION_BLOCK.get().defaultBlockState(), Block.UPDATE_CLIENTS);
        level.setBlock(origin.offset(9, 1, 3), GalacticraftBlocks.TIN_DECORATION_BLOCK.get().defaultBlockState(), Block.UPDATE_CLIENTS);
        level.setBlock(origin.offset(9, 1, 4), GalacticraftBlocks.TIN_DECORATION_BLOCK.get().defaultBlockState(), Block.UPDATE_CLIENTS);
        level.setBlock(origin.offset(9, 1, 5), GalacticraftBlocks.TIN_DECORATION_BLOCK.get().defaultBlockState(), Block.UPDATE_CLIENTS);
        level.setBlock(origin.offset(9, 1, 6), GalacticraftBlocks.TIN_DECORATION_BLOCK.get().defaultBlockState(), Block.UPDATE_CLIENTS);
        level.setBlock(origin.offset(9, 5, 0), GalacticraftBlocks.TIN_DECORATION_BLOCK.get().defaultBlockState(), Block.UPDATE_CLIENTS);
        level.setBlock(origin.offset(9, 5, 6), GalacticraftBlocks.TIN_DECORATION_BLOCK.get().defaultBlockState(), Block.UPDATE_CLIENTS);
        level.setBlock(origin.offset(9, 6, 0), GalacticraftBlocks.TIN_DECORATION_BLOCK.get().defaultBlockState(), Block.UPDATE_CLIENTS);
        level.setBlock(origin.offset(9, 6, 1), GalacticraftBlocks.TIN_DECORATION_BLOCK.get().defaultBlockState(), Block.UPDATE_CLIENTS);
        level.setBlock(origin.offset(9, 6, 2), GalacticraftBlocks.TIN_DECORATION_BLOCK.get().defaultBlockState(), Block.UPDATE_CLIENTS);
        level.setBlock(origin.offset(9, 6, 3), GalacticraftBlocks.TIN_DECORATION_BLOCK.get().defaultBlockState(), Block.UPDATE_CLIENTS);
        level.setBlock(origin.offset(9, 6, 4), GalacticraftBlocks.TIN_DECORATION_BLOCK.get().defaultBlockState(), Block.UPDATE_CLIENTS);
        level.setBlock(origin.offset(9, 6, 5), GalacticraftBlocks.TIN_DECORATION_BLOCK.get().defaultBlockState(), Block.UPDATE_CLIENTS);
        level.setBlock(origin.offset(9, 6, 6), GalacticraftBlocks.TIN_DECORATION_BLOCK.get().defaultBlockState(), Block.UPDATE_CLIENTS);
        level.setBlock(origin.offset(10, 1, 0), GalacticraftBlocks.TIN_DECORATION_BLOCK.get().defaultBlockState(), Block.UPDATE_CLIENTS);
        level.setBlock(origin.offset(10, 1, 1), GalacticraftBlocks.TIN_DECORATION_BLOCK.get().defaultBlockState(), Block.UPDATE_CLIENTS);
        level.setBlock(origin.offset(10, 1, 2), GalacticraftBlocks.TIN_DECORATION_BLOCK.get().defaultBlockState(), Block.UPDATE_CLIENTS);
        level.setBlock(origin.offset(10, 1, 3), GalacticraftBlocks.TIN_DECORATION_BLOCK.get().defaultBlockState(), Block.UPDATE_CLIENTS);
        level.setBlock(origin.offset(10, 1, 4), GalacticraftBlocks.TIN_DECORATION_BLOCK.get().defaultBlockState(), Block.UPDATE_CLIENTS);
        level.setBlock(origin.offset(10, 1, 5), GalacticraftBlocks.TIN_DECORATION_BLOCK.get().defaultBlockState(), Block.UPDATE_CLIENTS);
        level.setBlock(origin.offset(10, 1, 6), GalacticraftBlocks.TIN_DECORATION_BLOCK.get().defaultBlockState(), Block.UPDATE_CLIENTS);
        level.setBlock(origin.offset(10, 5, 0), GalacticraftBlocks.TIN_DECORATION_BLOCK.get().defaultBlockState(), Block.UPDATE_CLIENTS);
        level.setBlock(origin.offset(10, 5, 6), GalacticraftBlocks.TIN_DECORATION_BLOCK.get().defaultBlockState(), Block.UPDATE_CLIENTS);
        level.setBlock(origin.offset(10, 6, 0), GalacticraftBlocks.TIN_DECORATION_BLOCK.get().defaultBlockState(), Block.UPDATE_CLIENTS);
        level.setBlock(origin.offset(10, 6, 1), GalacticraftBlocks.TIN_DECORATION_BLOCK.get().defaultBlockState(), Block.UPDATE_CLIENTS);
        level.setBlock(origin.offset(10, 6, 2), GalacticraftBlocks.TIN_DECORATION_BLOCK.get().defaultBlockState(), Block.UPDATE_CLIENTS);
        level.setBlock(origin.offset(10, 6, 3), GalacticraftBlocks.TIN_DECORATION_BLOCK.get().defaultBlockState(), Block.UPDATE_CLIENTS);
        level.setBlock(origin.offset(10, 6, 4), GalacticraftBlocks.TIN_DECORATION_BLOCK.get().defaultBlockState(), Block.UPDATE_CLIENTS);
        level.setBlock(origin.offset(10, 6, 5), GalacticraftBlocks.TIN_DECORATION_BLOCK.get().defaultBlockState(), Block.UPDATE_CLIENTS);
        level.setBlock(origin.offset(10, 6, 6), GalacticraftBlocks.TIN_DECORATION_BLOCK.get().defaultBlockState(), Block.UPDATE_CLIENTS);
        level.setBlock(origin.offset(11, 1, 0), GalacticraftBlocks.TIN_DECORATION_BLOCK.get().defaultBlockState(), Block.UPDATE_CLIENTS);
        level.setBlock(origin.offset(11, 1, 1), GalacticraftBlocks.TIN_DECORATION_BLOCK.get().defaultBlockState(), Block.UPDATE_CLIENTS);
        level.setBlock(origin.offset(11, 1, 2), GalacticraftBlocks.TIN_DECORATION_BLOCK.get().defaultBlockState(), Block.UPDATE_CLIENTS);
        level.setBlock(origin.offset(11, 1, 3), GalacticraftBlocks.TIN_DECORATION_BLOCK.get().defaultBlockState(), Block.UPDATE_CLIENTS);
        level.setBlock(origin.offset(11, 1, 4), GalacticraftBlocks.TIN_DECORATION_BLOCK.get().defaultBlockState(), Block.UPDATE_CLIENTS);
        level.setBlock(origin.offset(11, 1, 5), GalacticraftBlocks.TIN_DECORATION_BLOCK.get().defaultBlockState(), Block.UPDATE_CLIENTS);
        level.setBlock(origin.offset(11, 1, 6), GalacticraftBlocks.TIN_DECORATION_BLOCK.get().defaultBlockState(), Block.UPDATE_CLIENTS);
        level.setBlock(origin.offset(11, 5, 0), GalacticraftBlocks.TIN_DECORATION_BLOCK.get().defaultBlockState(), Block.UPDATE_CLIENTS);
        level.setBlock(origin.offset(11, 5, 6), GalacticraftBlocks.TIN_DECORATION_BLOCK.get().defaultBlockState(), Block.UPDATE_CLIENTS);
        level.setBlock(origin.offset(11, 6, 0), GalacticraftBlocks.TIN_DECORATION_BLOCK.get().defaultBlockState(), Block.UPDATE_CLIENTS);
        level.setBlock(origin.offset(11, 6, 1), GalacticraftBlocks.TIN_DECORATION_BLOCK.get().defaultBlockState(), Block.UPDATE_CLIENTS);
        level.setBlock(origin.offset(11, 6, 2), GalacticraftBlocks.TIN_DECORATION_BLOCK.get().defaultBlockState(), Block.UPDATE_CLIENTS);
        level.setBlock(origin.offset(11, 6, 3), GalacticraftBlocks.TIN_DECORATION_BLOCK.get().defaultBlockState(), Block.UPDATE_CLIENTS);
        level.setBlock(origin.offset(11, 6, 4), GalacticraftBlocks.TIN_DECORATION_BLOCK.get().defaultBlockState(), Block.UPDATE_CLIENTS);
        level.setBlock(origin.offset(11, 6, 5), GalacticraftBlocks.TIN_DECORATION_BLOCK.get().defaultBlockState(), Block.UPDATE_CLIENTS);
        level.setBlock(origin.offset(11, 6, 6), GalacticraftBlocks.TIN_DECORATION_BLOCK.get().defaultBlockState(), Block.UPDATE_CLIENTS);
        level.setBlock(origin.offset(12, 1, 0), GalacticraftBlocks.TIN_DECORATION_BLOCK.get().defaultBlockState(), Block.UPDATE_CLIENTS);
        level.setBlock(origin.offset(12, 1, 1), GalacticraftBlocks.TIN_DECORATION_BLOCK.get().defaultBlockState(), Block.UPDATE_CLIENTS);
        level.setBlock(origin.offset(12, 1, 2), GalacticraftBlocks.TIN_DECORATION_BLOCK.get().defaultBlockState(), Block.UPDATE_CLIENTS);
        level.setBlock(origin.offset(12, 1, 3), GalacticraftBlocks.TIN_DECORATION_BLOCK.get().defaultBlockState(), Block.UPDATE_CLIENTS);
        level.setBlock(origin.offset(12, 1, 4), GalacticraftBlocks.TIN_DECORATION_BLOCK.get().defaultBlockState(), Block.UPDATE_CLIENTS);
        level.setBlock(origin.offset(12, 1, 5), GalacticraftBlocks.TIN_DECORATION_BLOCK.get().defaultBlockState(), Block.UPDATE_CLIENTS);
        level.setBlock(origin.offset(12, 1, 6), GalacticraftBlocks.TIN_DECORATION_BLOCK.get().defaultBlockState(), Block.UPDATE_CLIENTS);
        level.setBlock(origin.offset(12, 2, 0), GalacticraftBlocks.TIN_DECORATION_BLOCK.get().defaultBlockState(), Block.UPDATE_CLIENTS);
        level.setBlock(origin.offset(12, 2, 6), GalacticraftBlocks.TIN_DECORATION_BLOCK.get().defaultBlockState(), Block.UPDATE_CLIENTS);
        level.setBlock(origin.offset(12, 3, 0), Blocks.GLASS_PANE.defaultBlockState(), Block.UPDATE_ALL);
        level.setBlock(origin.offset(12, 3, 6), Blocks.GLASS_PANE.defaultBlockState(), Block.UPDATE_ALL);
        level.setBlock(origin.offset(12, 4, 0), GalacticraftBlocks.TIN_DECORATION_BLOCK.get().defaultBlockState(), Block.UPDATE_CLIENTS);
        level.setBlock(origin.offset(12, 4, 6), GalacticraftBlocks.TIN_DECORATION_BLOCK.get().defaultBlockState(), Block.UPDATE_CLIENTS);
        level.setBlock(origin.offset(12, 5, 0), GalacticraftBlocks.TIN_DECORATION_BLOCK.get().defaultBlockState(), Block.UPDATE_CLIENTS);
        level.setBlock(origin.offset(12, 5, 6), GalacticraftBlocks.TIN_DECORATION_BLOCK.get().defaultBlockState(), Block.UPDATE_CLIENTS);
        level.setBlock(origin.offset(12, 6, 0), GalacticraftBlocks.TIN_DECORATION_BLOCK.get().defaultBlockState(), Block.UPDATE_CLIENTS);
        level.setBlock(origin.offset(12, 6, 1), GalacticraftBlocks.TIN_DECORATION_BLOCK.get().defaultBlockState(), Block.UPDATE_CLIENTS);
        level.setBlock(origin.offset(12, 6, 2), GalacticraftBlocks.TIN_DECORATION_BLOCK.get().defaultBlockState(), Block.UPDATE_CLIENTS);
        level.setBlock(origin.offset(12, 6, 3), GalacticraftBlocks.TIN_DECORATION_BLOCK.get().defaultBlockState(), Block.UPDATE_CLIENTS);
        level.setBlock(origin.offset(12, 6, 4), GalacticraftBlocks.TIN_DECORATION_BLOCK.get().defaultBlockState(), Block.UPDATE_CLIENTS);
        level.setBlock(origin.offset(12, 6, 5), GalacticraftBlocks.TIN_DECORATION_BLOCK.get().defaultBlockState(), Block.UPDATE_CLIENTS);
        level.setBlock(origin.offset(12, 6, 6), GalacticraftBlocks.TIN_DECORATION_BLOCK.get().defaultBlockState(), Block.UPDATE_CLIENTS);
        level.setBlock(origin.offset(13, 1, 0), GalacticraftBlocks.TIN_DECORATION_BLOCK.get().defaultBlockState(), Block.UPDATE_CLIENTS);
        level.setBlock(origin.offset(13, 1, 1), GalacticraftBlocks.TIN_DECORATION_BLOCK.get().defaultBlockState(), Block.UPDATE_CLIENTS);
        level.setBlock(origin.offset(13, 1, 2), GalacticraftBlocks.TIN_DECORATION_BLOCK.get().defaultBlockState(), Block.UPDATE_CLIENTS);
        level.setBlock(origin.offset(13, 1, 3), GalacticraftBlocks.TIN_DECORATION_BLOCK.get().defaultBlockState(), Block.UPDATE_CLIENTS);
        level.setBlock(origin.offset(13, 1, 4), GalacticraftBlocks.TIN_DECORATION_BLOCK.get().defaultBlockState(), Block.UPDATE_CLIENTS);
        level.setBlock(origin.offset(13, 1, 5), GalacticraftBlocks.TIN_DECORATION_BLOCK.get().defaultBlockState(), Block.UPDATE_CLIENTS);
        level.setBlock(origin.offset(13, 1, 6), GalacticraftBlocks.TIN_DECORATION_BLOCK.get().defaultBlockState(), Block.UPDATE_CLIENTS);
        level.setBlock(origin.offset(13, 2, 0), GalacticraftBlocks.TIN_DECORATION_BLOCK.get().defaultBlockState(), Block.UPDATE_CLIENTS);
        level.setBlock(origin.offset(13, 2, 1), GalacticraftBlocks.TIN_DECORATION_BLOCK.get().defaultBlockState(), Block.UPDATE_CLIENTS);
        level.setBlock(origin.offset(13, 2, 5), GalacticraftBlocks.TIN_DECORATION_BLOCK.get().defaultBlockState(), Block.UPDATE_CLIENTS);
        level.setBlock(origin.offset(13, 2, 6), GalacticraftBlocks.TIN_DECORATION_BLOCK.get().defaultBlockState(), Block.UPDATE_CLIENTS);
        level.setBlock(origin.offset(13, 3, 0), GalacticraftBlocks.TIN_DECORATION_BLOCK.get().defaultBlockState(), Block.UPDATE_CLIENTS);
        level.setBlock(origin.offset(13, 3, 1), Blocks.GLASS_PANE.defaultBlockState(), Block.UPDATE_ALL);
        level.setBlock(origin.offset(13, 3, 5), Blocks.GLASS_PANE.defaultBlockState(), Block.UPDATE_ALL);
        level.setBlock(origin.offset(13, 3, 6), GalacticraftBlocks.TIN_DECORATION_BLOCK.get().defaultBlockState(), Block.UPDATE_CLIENTS);
        level.setBlock(origin.offset(13, 4, 0), GalacticraftBlocks.TIN_DECORATION_BLOCK.get().defaultBlockState(), Block.UPDATE_CLIENTS);
        level.setBlock(origin.offset(13, 4, 1), GalacticraftBlocks.TIN_DECORATION_BLOCK.get().defaultBlockState(), Block.UPDATE_CLIENTS);
        level.setBlock(origin.offset(13, 4, 5), GalacticraftBlocks.TIN_DECORATION_BLOCK.get().defaultBlockState(), Block.UPDATE_CLIENTS);
        level.setBlock(origin.offset(13, 4, 6), GalacticraftBlocks.TIN_DECORATION_BLOCK.get().defaultBlockState(), Block.UPDATE_CLIENTS);
        level.setBlock(origin.offset(13, 5, 0), GalacticraftBlocks.TIN_DECORATION_BLOCK.get().defaultBlockState(), Block.UPDATE_CLIENTS);
        level.setBlock(origin.offset(13, 5, 1), GalacticraftBlocks.TIN_DECORATION_BLOCK.get().defaultBlockState(), Block.UPDATE_CLIENTS);
        level.setBlock(origin.offset(13, 5, 2), GalacticraftBlocks.TIN_DECORATION_BLOCK.get().defaultBlockState(), Block.UPDATE_CLIENTS);
        level.setBlock(origin.offset(13, 5, 3), GalacticraftBlocks.TIN_DECORATION_BLOCK.get().defaultBlockState(), Block.UPDATE_CLIENTS);
        level.setBlock(origin.offset(13, 5, 4), GalacticraftBlocks.TIN_DECORATION_BLOCK.get().defaultBlockState(), Block.UPDATE_CLIENTS);
        level.setBlock(origin.offset(13, 5, 5), GalacticraftBlocks.TIN_DECORATION_BLOCK.get().defaultBlockState(), Block.UPDATE_CLIENTS);
        level.setBlock(origin.offset(13, 5, 6), GalacticraftBlocks.TIN_DECORATION_BLOCK.get().defaultBlockState(), Block.UPDATE_CLIENTS);
        level.setBlock(origin.offset(13, 6, 0), GalacticraftBlocks.TIN_DECORATION_BLOCK.get().defaultBlockState(), Block.UPDATE_CLIENTS);
        level.setBlock(origin.offset(13, 6, 1), GalacticraftBlocks.TIN_DECORATION_BLOCK.get().defaultBlockState(), Block.UPDATE_CLIENTS);
        level.setBlock(origin.offset(13, 6, 2), GalacticraftBlocks.TIN_DECORATION_BLOCK.get().defaultBlockState(), Block.UPDATE_CLIENTS);
        level.setBlock(origin.offset(13, 6, 3), GalacticraftBlocks.TIN_DECORATION_BLOCK.get().defaultBlockState(), Block.UPDATE_CLIENTS);
        level.setBlock(origin.offset(13, 6, 4), GalacticraftBlocks.TIN_DECORATION_BLOCK.get().defaultBlockState(), Block.UPDATE_CLIENTS);
        level.setBlock(origin.offset(13, 6, 5), GalacticraftBlocks.TIN_DECORATION_BLOCK.get().defaultBlockState(), Block.UPDATE_CLIENTS);
        level.setBlock(origin.offset(13, 6, 6), GalacticraftBlocks.TIN_DECORATION_BLOCK.get().defaultBlockState(), Block.UPDATE_CLIENTS);

        return true;
    }
}
